File: SigMinerOutput/Signature.txt
Sig1	Sig2	Sig3	Sig4	Sig5
A[C>A]A	693.194756309365	1035.30666442829	428.937102527147	396.231935632884	1310.32954110238
A[C>A]C	791.074684710284	781.453614761375	862.252032100865	168.760029792618	814.459638634925
A[C>A]G	390.692252577935	217.474557042933	720.74555573391	171.624121228372	389.463513416917
A[C>A]T	246.813355703531	30.323736323244	753.942008741824	86.8094949737653	509.111404257703
A[C>G]A	1420.30731732979	873.165141061284	674.640050012012	360.364839321358	368.52265227562
A[C>G]C	942.091888664263	666.848760562743	411.27433671908	88.4090673132099	210.375946740769
A[C>G]G	606.912089489985	588.727030148361	442.930529885685	77.6316700736117	171.798680402422
A[C>G]T	1078.22950174323	336.670297778019	444.066706541888	331.402756391378	365.630737545552
A[C>T]A	4827.71166357631	1626.00467897565	1247.43577564737	1220.5510440336	1060.29683776714
A[C>T]C	2745.06466984707	1881.15870865055	959.244832945465	684.115452925302	455.416335631682
A[C>T]G	9543.64765755589	3841.42091074026	3909.44159307987	1425.83954475732	925.650293866742
A[C>T]T	4174.43838572182	1118.55533238778	1039.56053522541	815.405825702161	846.039920962891
A[T>A]A	593.742304943893	147.581726896212	32.0861098684677	414.975385648553	364.61447264294
A[T>A]C	713.191498248264	284.031206028701	86.8468141004654	350.6941666141	244.236315008536
A[T>A]G	780.084644978661	348.680260410701	274.028646537679	231.00391816497	299.202529908056
A[T>A]T	732.318041917668	37.9666492284227	231.378849929762	249.777675291164	186.55878363305
A[T>C]A	5604.13090284784	167.481559470965	609.752267393277	1637.08474066958	1097.5505296184
A[T>C]C	2063.53744929255	1118.26720470806	829.358016477883	573.276873436667	457.56045608491
A[T>C]G	7783.15306932064	2667.36266256659	2305.10833204756	1770.62953590951	581.746400155769
A[T>C]T	5095.32334133965	190.471375185727	631.831074224395	1362.37498888914	903.999220361156
A[T>G]A	252.149805856865	0.00138026170548741	453.208534385676	820.281035195174	13.3592443006455
A[T>G]C	283.501177855063	228.756792504064	250.610034891482	452.455434894183	56.6765598552739
A[T>G]G	733.86429742317	597.13564387707	246.446194644697	329.667290907239	201.88657314789
A[T>G]T	711.622063545463	24.578026201954	298.033106239287	228.386639743601	173.38016426976
C[C>A]A	1.05940769122939e-07	264.016998771413	1743.68636407749	101.426983524615	1167.86965352061
C[C>A]C	0.0318450815412585	597.164688841235	2469.05825484464	96.3714032021529	1175.3738080305
C[C>A]G	418.385644716662	544.765599158379	1338.18369895672	20.375648423073	553.289408745234
C[C>A]T	3.01907805518671	206.077867424821	1789.38209828677	105.956525152014	710.564431081273
C[C>G]A	527.144879215988	777.844524867148	521.412423164121	282.073121907336	119.525050845473
C[C>G]C	1162.12951479873	1319.82417456197	797.568572815392	358.665374889151	303.812362934829
C[C>G]G	895.742793598761	1075.74487936819	547.363961287685	151.548392960526	254.599972784906
C[C>G]T	1165.70255650949	996.022370209288	619.491072703725	316.823015598806	394.960984978756
C[C>T]A	3125.07058389635	2259.43447834769	1370.64285945943	680.303338767549	644.54873952905
C[C>T]C	3047.69442570878	3748.62336748381	1823.63605836015	1323.21559464803	821.830553799297
C[C>T]G	9451.69344549353	8465.00866951078	4332.39792892727	1512.92644601558	437.973510052911
C[C>T]T	4410.36633567461	3335.22294294435	1640.3553027121	1208.92396829144	1039.13145037755
C[T>A]A	94.5984510354723	56.2243569315247	221.823299643703	43.4804502941369	324.87344209523
C[T>A]C	378.725878154448	635.2237647586	131.799223994533	130.95583895634	378.295294136146
C[T>A]G	332.75464062193	262.653724639871	1084.23114434221	43.8440535238681	453.516436872189
C[T>A]T	321.509030508584	176.995511751167	371.605539949042	199.059451983737	446.830465807536
C[T>C]A	2530.86260702591	1046.24420855331	532.42030307437	692.883808996968	600.589072349507
C[T>C]C	1851.66697214935	3046.39020348844	1032.73562149805	2201.06220994493	422.14499291929
C[T>C]G	5957.08104776488	6242.29776315722	2830.17059936662	1248.33628463305	314.114305078289
C[T>C]T	3303.10595198841	1731.36054458483	1182.51333583978	1107.27946649502	518.74070109203
C[T>G]A	339.955629116027	3.48190646575657e-06	260.145319676865	88.2172945529646	66.681753172303
C[T>G]C	606.681206544321	841.095868892755	252.506018995194	311.04928723761	40.6676183301864
C[T>G]G	605.988096471717	954.770099114829	470.749889502994	328.48629958324	251.005615327285
C[T>G]T	800.677057771934	203.716173673509	251.554045562182	162.23718529496	209.815537697481
G[C>A]A	471.997538989216	909.061540424304	894.355262344646	209.327176127047	857.258482114853
G[C>A]C	367.121812515521	787.779177895011	1526.31175984801	169.943919713896	441.843330027627
G[C>A]G	830.381420518511	432.077819481359	1002.35022784838	109.127158828371	427.063373323443
G[C>A]T	381.254707611539	332.985485548157	757.07613773465	0.492512835510981	358.191156270209
G[C>G]A	746.995858047607	635.117665855062	577.516005633789	247.106041494476	279.264428969133
G[C>G]C	871.396459952862	887.415655565376	625.266982061846	188.461126616138	233.459775803844
G[C>G]G	325.055804109085	1336.84425820639	357.677726766873	872.895061222202	247.527149695512
G[C>G]T	877.629841725478	643.433268320491	520.278963675171	106.670465609129	222.987460669796
G[C>T]A	2583.36886460882	1636.18924781218	691.161525439499	763.753020733145	607.527341406421
G[C>T]C	2680.95219641431	3138.23134498899	1184.38009378089	827.707558744629	434.728806071239
G[C>T]G	6425.53334554752	6432.68667284693	2705.77172280256	1131.67243794643	777.335820856632
G[C>T]T	2896.19299512876	1904.35884717006	1108.18110386085	667.168240910791	588.098812929607
G[T>A]A	139.347025391192	75.7091056705985	210.054412950245	110.112272399148	203.777183588883
G[T>A]C	172.688795097194	240.374333355266	342.194210505895	188.554543306012	172.188117735699
G[T>A]G	195.508167297245	673.300482466836	192.96424453506	232.020473488596	491.206632212329
G[T>A]T	691.040669976894	91.1227361803519	225.039867088782	211.471925992899	123.324800761139
G[T>C]A	1981.91042880745	765.675581359127	603.738705973093	698.339050329644	350.336233530751
G[T>C]C	1683.0613554624	1540.20981165208	1036.98043801573	441.599205255492	405.14918961436
G[T>C]G	4109.9184666549	4600.60169436176	1717.2383628627	788.829632001517	195.411844119182
G[T>C]T	2786.01112096518	1011.37559547525	542.906424330809	712.702933571915	295.003925656906
G[T>G]A	316.182982142986	212.498840580766	276.329330530832	238.954963801903	262.033882943579
G[T>G]C	610.761402256087	333.436997844433	352.19552929788	136.70762778592	182.898442815746
G[T>G]G	0.209478221034516	1743.45593364627	0.985999456319317	2472.93670425938	677.411884417067
G[T>G]T	937.097582173	408.639405868442	256.88461668983	257.331983906451	217.046411362342
T[C>A]A	241.752639826391	2.21567751853967	959.400302307431	19.1503587241627	807.481021623541
T[C>A]C	417.784487991865	31.9156968644726	1167.39838680768	274.185027582905	782.716400753138
T[C>A]G	110.563928334984	120.874854656335	459.211445073052	83.7537048421089	212.596067093586
T[C>A]T	521.073942226879	311.269618422073	721.142694303642	300.539488553959	698.974256493513
T[C>G]A	1291.04324152524	301.56616779622	38.3694481087429	394.744771384327	1064.27637118553
T[C>G]C	1022.07508120628	626.7009167157	586.400022587193	235.473159850718	661.350819640172
T[C>G]G	607.033273675166	308.711764855849	333.517937856974	104.775272726235	192.961750885841
T[C>G]T	1713.10608955723	419.826956540114	700.541007159771	431.495129073775	1549.03081766918
T[C>T]A	2664.3571023685	994.081509573899	614.076227409322	576.099335927908	1445.38582472044
T[C>T]C	2804.89565802583	2368.11822818908	1251.68797194128	1347.62053501262	899.677606831261
T[C>T]G	5238.73894129399	2649.57306656847	1409.22600814359	813.143673100613	764.3183108934
T[C>T]T	3723.07539172302	1627.47088758553	0.312408139718976	820.606723185195	2085.5345893666
T[T>A]A	780.51913656565	0.0107681751489791	121.064661816354	221.894506721689	498.510926721224
T[T>A]C	384.67690190923	0.0111511359653913	156.564497128089	104.088935022998	212.658514803784
T[T>A]G	356.6063719694	78.3862679919311	165.708826315258	66.3822915093817	267.916242214095
T[T>A]T	694.48848084618	47.730851353063	57.3725596379904	304.654229563389	229.753878599444
T[T>C]A	2539.71675620062	263.537692384563	464.556440248918	859.162136636231	322.026974529729
T[T>C]C	2239.43603775097	1358.08847616863	503.783911264346	955.296291732605	499.395283083514
T[T>C]G	3158.54606962589	1553.28663988652	1172.56493234672	637.894465320705	341.707892820233
T[T>C]T	2892.83082220005	251.019971480472	714.983217240247	863.153486322091	877.012502757211
T[T>G]A	376.370391377899	8.88092115020026	314.536140721438	739.852162588733	51.3603841617964
T[T>G]C	442.343187514123	128.395373950035	574.175432499457	1029.46255112285	48.6234549135981
T[T>G]G	808.904458231326	461.38846566496	257.850579201197	240.216368642933	137.640128259649
T[T>G]T	1350.84820647461	80.135464497066	360.147940107997	652.558315676899	274.310073243493