File: SigMinerOutput/Signature.norm.txt
Sig1	Sig2	Sig3	Sig4	Sig5
A[C>A]A	0.00423713721640902	0.0101141773017263	0.00560182006971307	0.00779625867683319	0.0275077535044368
A[C>A]C	0.00483542605744851	0.0076342215155507	0.0112608135554508	0.00332052196770011	0.0170979545802148
A[C>A]G	0.00238809752741674	0.00212456492759201	0.00941277146574465	0.00337687582436634	0.00817600915646866
A[C>A]T	0.00150864103549495	0.000296240385734841	0.00984630951970968	0.00170806342840518	0.01068777782636
A[C>G]A	0.00868159624437542	0.00853017502331783	0.00881064414741398	0.00709053777025129	0.00773639757146173
A[C>G]C	0.00575851528939571	0.00651461719459954	0.00537114840385033	0.00173953661016853	0.00441642312462788
A[C>G]G	0.00370973637359559	0.0057514259009696	0.00578457101795068	0.00152748056625403	0.00360657041199082
A[C>G]T	0.00659065335980047	0.00328901880085187	0.00579940922420041	0.00652067989147793	0.00767568759350944
A[C>T]A	0.0295092779823365	0.0158848582566382	0.0162912248031919	0.0240155596049211	0.0222588159237367
A[C>T]C	0.0167791454972687	0.0183775236513954	0.0125275172637284	0.0134606541174061	0.00956055702744119
A[C>T]G	0.0583353297209276	0.0375278296921241	0.0510564095492295	0.0280548156847344	0.0194321804678036
A[C>T]T	0.0255161598969951	0.0109274549679527	0.0135764218940207	0.0160439231977021	0.0177609195784299
A[T>A]A	0.00362923636443592	0.00144176387886725	0.000419037227512454	0.00816505475730319	0.00765435314018349
A[T>A]C	0.00435936684769957	0.00277477396379343	0.00113419945104384	0.00690025763575291	0.00512725397645739
A[T>A]G	0.00476824968899963	0.00340634721727922	0.003578751203398	0.00454523257571227	0.00628115995438097
A[T>A]T	0.00447627741181632	0.000370905969257687	0.00302175465262215	0.00491462497882098	0.00391642932048077
A[T>C]A	0.0342551229621349	0.00163617046567973	0.00796322460545491	0.0322112756857179	0.0230408828316633
A[T>C]C	0.0126133258283753	0.0109246401744829	0.0108312252642896	0.0112797944759794	0.00960556855703061
A[T>C]G	0.047574346503436	0.0260581524529266	0.03010418553501	0.0348389027773409	0.0122126045972492
A[T>C]T	0.0311450482894198	0.00186076389317546	0.00825156875310077	0.0268060872258121	0.0189776593916803
A[T>G]A	0.00154125996595049	1.34841318922562e-08	0.00591879939676295	0.0161398478087523	0.000280450671148378
A[T>G]C	0.00173289451579374	0.00223478398995719	0.00327290951250305	0.00890251212219897	0.00118981125669097
A[T>G]G	0.00448572886350261	0.00583357181293555	0.00321853071494952	0.00648653287650434	0.00423820566949555
A[T>G]T	0.00434977371369584	0.000240109064564276	0.00389224393537863	0.00449373501136353	0.00363977050939331
C[C>A]A	6.47560547018144e-13	0.00257925002126622	0.0227721435427845	0.00199567710034722	0.0245170924921144
C[C>A]C	1.94652338220845e-07	0.0058338555606669	0.0322453338817993	0.00189620351326124	0.0246746272389412
C[C>A]G	0.00255737275838407	0.00532195536557435	0.0174763718447606	0.000400911212673343	0.0116152068582496
C[C>A]T	1.84540460966302e-05	0.0020132277331058	0.0233689193392491	0.00208480035124893	0.0149168820560665
C[C>G]A	0.00322216111105243	0.00759896338736292	0.00680952652374864	0.00555007011400772	0.00250918988935902
C[C>G]C	0.00710349028555472	0.0128937020955002	0.010416062429309	0.00705709911189479	0.00637793419827874
C[C>G]G	0.00547520749766557	0.0105092286326219	0.0071484476528466	0.00298186583999458	0.00534481828724665
C[C>G]T	0.00712533042192429	0.0097303989193824	0.00809041116665858	0.00623380894434309	0.00829141759982368
C[C>T]A	0.0191019230229474	0.022072997017035	0.0179002810278992	0.013385646967788	0.0135310143688314
C[C>T]C	0.0186289630120194	0.0366212666051584	0.0238162681926723	0.0260355870725519	0.0172526922329071
C[C>T]G	0.0577732616865278	0.0826968486591952	0.0565801221793634	0.0297683373585713	0.00919437971754246
C[C>T]T	0.0269582641368747	0.032582651444973	0.021422663607449	0.0237867852886959	0.0218144908582658
C[T>A]A	0.000578230885113853	0.000549270215501809	0.00289696135995935	0.000855521242468337	0.00682006952066056
C[T>A]C	0.00231495333532101	0.0062056644700403	0.00172126760262818	0.00257668679359374	0.00794155468267234
C[T>A]G	0.00203395518918604	0.00256593184535659	0.0141598097921589	0.000862675498801031	0.00952067244488377
C[T>A]T	0.00196521665257886	0.00172911471447896	0.00485308302648255	0.00391669333077623	0.00938031382652466
C[T>C]A	0.0154698402494286	0.0102210289857025	0.0069532869078304	0.0136331802718063	0.0126081688929562
C[T>C]C	0.0113182723450781	0.0297609700651728	0.0134872900878265	0.0433080951062761	0.0088620915915447
C[T>C]G	0.0364125227130031	0.0609826136699372	0.0369613781853725	0.0245622619366384	0.0065942029125297
C[T>C]T	0.0201901601700318	0.016914106827289	0.0154433526463041	0.0217868282993205	0.0108899256948396
C[T>G]A	0.00207797106793521	3.40156405369382e-11	0.00339743814238022	0.00173576328976806	0.00139985032159485
C[T>G]C	0.00370832510682992	0.00821688204859432	0.00329767062955601	0.00612020507805768	0.000853735480693002
C[T>G]G	0.00370408848724074	0.00932739486436781	0.00614788546688191	0.00646329569386211	0.00526936192619421
C[T>G]T	0.00489412034486924	0.00199015573892875	0.00328523807510581	0.0031921784939938	0.00440465845525208
G[C>A]A	0.00288507424544356	0.00888085618874011	0.0116800743711338	0.00411872104799127	0.0179964308793375
G[C>A]C	0.00224402374744859	0.00769601757005808	0.0199332811234592	0.00334381618313592	0.00927561886436156
G[C>A]G	0.00507568758803959	0.00422107943909643	0.0130904638236259	0.00214718573235375	0.00896534317181867
G[C>A]T	0.0023304107479876	0.00325302092167568	0.00988724052472101	9.69068144689329e-06	0.00751950843286395
G[C>G]A	0.00456599522980861	0.00620462796254086	0.00754222642872246	0.00486205791822936	0.00586259931847173
G[C>G]C	0.00532639108577669	0.00866939196771451	0.00816584321665503	0.00370816070461355	0.00490102204412671
G[C>G]G	0.00198689622572056	0.0130599756737399	0.0046711889843225	0.017175081266856	0.00519633848272369
G[C>G]T	0.00536449249039991	0.00628586522353392	0.00679472380307935	0.0020988478420819	0.00468117668897597
G[C>T]A	0.0157907835573142	0.0159843539311987	0.00902641082296081	0.01502760272298	0.0127538240041158
G[C>T]C	0.0163872594583952	0.0306581898171991	0.0154677320763842	0.016285972069455	0.00912626363336442
G[C>T]G	0.039275926752028	0.0628425719364548	0.0353367574209745	0.0222667843508893	0.016318614119242
G[C>T]T	0.0177029139558097	0.0186041717765097	0.0144725907642639	0.0131272008118182	0.0123459608250223
G[T>A]A	0.000851755530328056	0.000739621741477359	0.0027432624020255	0.00216656882476293	0.00427789526234407
G[T>A]C	0.00105555634098969	0.00234827873698849	0.00446897781716195	0.00370999877119399	0.00361474587154749
G[T>A]G	0.00119503923569406	0.00657764572660986	0.00252006872663833	0.00456523431597998	0.0103119028723672
G[T>A]T	0.00422397041258716	0.00089020146552949	0.00293896899222821	0.00416092114154148	0.00258895805513716
G[T>C]A	0.0121143825181237	0.00748008184584133	0.00788468887409577	0.0137405175880329	0.0073546100071354
G[T>C]C	0.0102876743394563	0.0150467061134104	0.0135427264168847	0.00868890497217672	0.00850529862209934
G[T>C]G	0.0251217833559294	0.0449444621870493	0.0224267387197094	0.015521010070054	0.00410228165607531
G[T>C]T	0.0170294297504794	0.00988038852905915	0.00709023324369569	0.0140231413224921	0.00619301863787967
G[T>G]A	0.00193266130281479	0.00207595587268047	0.00360879760808294	0.00470167733183176	0.00550087839411629
G[T>G]C	0.00373326521052113	0.00325743186152119	0.00459959274415814	0.00268985897770429	0.00383958777048419
G[T>G]G	1.2804308721233e-06	0.0170322697964884	1.28769265017967e-05	0.0486574970466399	0.0142209105061035
G[T>G]T	0.00572798770430988	0.00399210354326064	0.00335485411006749	0.00506326353819238	0.00455645621616296
T[C>A]A	0.00147770752454506	2.1645524013249e-05	0.012529547657898	0.000376802415305697	0.0169514524442792
T[C>A]C	0.00255369820154654	0.000311792658046572	0.0152459548825252	0.00539486398777184	0.0164315686553807
T[C>A]G	0.000675819502782658	0.00118085756937504	0.00599719603199716	0.00164793770862832	0.00446303012042535
T[C>A]T	0.00318505264648184	0.00304087302586818	0.0094179580042774	0.0059134143027298	0.0146735694727562
T[C>G]A	0.00789147251457079	0.00294607751895176	0.000501096182197872	0.00776699723641404	0.0223423582853351
T[C>G]C	0.0062474107386506	0.00612240257365411	0.00765824965025317	0.00463316936509731	0.0138837405064637
T[C>G]G	0.00371047710917732	0.00301588469596602	0.0043556676885471	0.00206155803116867	0.00405084683864082
T[C>G]T	0.0104713220947684	0.0041013976055449	0.00914890470058193	0.00849009719188694	0.0325188103958732
T[C>T]A	0.0162858223226533	0.0097114381522409	0.00801969453042948	0.0113353292416267	0.0303429906279663
T[C>T]C	0.0171448610546922	0.0231347565453765	0.0163467575104332	0.0265157786244295	0.0188869357408788
T[C>T]G	0.0320216728894319	0.0258843613104245	0.0184041680905437	0.0159994130881876	0.0160453374784598
T[C>T]T	0.02275721383952	0.015899182025963	4.07997857193695e-06	0.0161462560449135	0.043781636305787
T[T>A]A	0.00477090550896464	1.05197074852174e-07	0.00158107668537011	0.00436599581658511	0.0104652419573622
T[T>A]C	0.00235132883296812	1.08938317645145e-07	0.00204469638333783	0.0020480536520591	0.00446434108546518
T[T>A]G	0.00217974835575041	0.000765775629319288	0.00216411922287059	0.00130613781885464	0.00562436678673985
T[T>A]T	0.0042450450782802	0.000466294973203721	0.000749272455419182	0.0059943759376027	0.00482322412870641
T[T>C]A	0.0155239610353208	0.00257456755379546	0.00606700044171662	0.016904872273503	0.00676031361522299
T[T>C]C	0.0136885019584416	0.0132675159074592	0.00657930220606307	0.018796407693567	0.0104838072541527
T[T>C]G	0.0193065411697683	0.0151744570145218	0.0153134287809618	0.0125512100689637	0.00717347521472467
T[T>C]T	0.0176823627500849	0.00245227871611333	0.00933751664812196	0.0169834060609701	0.0184111271168156
T[T>G]A	0.00230055547585535	8.67600047425352e-05	0.00410776977641362	0.014557329491736	0.00107820875825426
T[T>G]C	0.00270381269503519	0.00125432745820217	0.00749859931062521	0.0202557028469875	0.00102075239116726
T[T>G]G	0.00494441014346263	0.0045074226864789	0.00336746935866894	0.00472649673065475	0.00288947978483351
T[T>G]T	0.00825702900559525	0.000782863980236321	0.00470344940336588	0.0128397359556837	0.0057585925081242